2019-03-22 17:35:05,565 - logger.py - INFO 开始登录前获取验证码操作,使用手机号18358331453
2019-03-22 17:35:05,649 - logger.py - ERROR 登录失败
Traceback (most recent call last):
  File "D:\py_workspace\dayan\case\test_日志登录测试.py", line 19, in test_login
    self.assertEqual(r.json()['message'],'请求成功142242')
  File "C:\Python34\lib\unittest\case.py", line 797, in assertEqual
    assertion_func(first, second, msg=msg)
  File "C:\Python34\lib\unittest\case.py", line 1170, in assertMultiLineEqual
    self.fail(self._formatMessage(msg, standardMsg))
  File "C:\Python34\lib\unittest\case.py", line 642, in fail
    raise self.failureException(msg)
AssertionError: '请求成功' != '请求成功142242'
- 请求成功
+ 请求成功142242

2019-03-22 17:35:05,654 - logger.py - INFO 获取验证码操作结果{'code': '000000', 'data': None, 'message': '请求成功', 'sysMark': None}
2019-03-22 17:35:05,658 - logger.py - INFO 获取是否获取验证码成功:请求成功
2019-03-22 17:35:05,661 - logger.py - INFO 开始执行登录操作
2019-03-22 17:35:05,701 - logger.py - INFO 获取是否登录成功结果:请求成功
2019-03-22 17:35:05,705 - logger.py - INFO 获取登录成功之后的token:eyJ0eXAiOiJKV1QiLCJhbGciOiJIUzI1NiJ9.eyJ1aWQiOiIxMDk3Njg0MTI4Mjc2OTcxNTIyIiwiaXNzIjoiZGF5YW4iLCJuYW1lIjoi5p2o5YWI55SfIiwiZXhwIjoxNTUzNDIwMTAzLCJfIjoxNTUzMjQ3MzAzODMwfQ.bk5yH2qCJWhlzuj2nhMq06GG6XqYzZyCdHWeAjjGwEI
2019-03-22 17:44:50,926 - logger.py - INFO 开始登录前获取验证码操作,使用手机号18358331453
2019-03-22 17:44:50,997 - logger.py - ERROR 登录失败
Traceback (most recent call last):
  File "D:\py_workspace\dayan\case\test_日志登录测试.py", line 19, in test_login
    self.assertEqual(r.json()['message'],'请求成功142242')
  File "C:\Python34\lib\unittest\case.py", line 797, in assertEqual
    assertion_func(first, second, msg=msg)
  File "C:\Python34\lib\unittest\case.py", line 1170, in assertMultiLineEqual
    self.fail(self._formatMessage(msg, standardMsg))
  File "C:\Python34\lib\unittest\case.py", line 642, in fail
    raise self.failureException(msg)
AssertionError: '请求成功' != '请求成功142242'
- 请求成功
+ 请求成功142242

2019-03-22 17:44:51,001 - logger.py - INFO 获取验证码操作结果{'message': '请求成功', 'code': '000000', 'data': None, 'sysMark': None}
2019-03-22 17:44:51,004 - logger.py - INFO 获取是否获取验证码成功:请求成功
2019-03-22 17:44:51,007 - logger.py - INFO 开始执行登录操作
2019-03-22 17:44:51,046 - logger.py - INFO 获取是否登录成功结果:请求成功
2019-03-22 17:44:51,050 - logger.py - INFO 获取登录成功之后的token:eyJ0eXAiOiJKV1QiLCJhbGciOiJIUzI1NiJ9.eyJ1aWQiOiIxMDk3Njg0MTI4Mjc2OTcxNTIyIiwiaXNzIjoiZGF5YW4iLCJuYW1lIjoi5p2o5YWI55SfIiwiZXhwIjoxNTUzNDIwNjg5LCJfIjoxNTUzMjQ3ODg5MTgyfQ.FIgXjD9cV0Qf2xPWdjmAAmXlIIr1cksOEP-idqrY7Ao
2019-03-22 17:44:58,935 - logger.py - INFO 开始登录前获取验证码操作,使用手机号18358331453
2019-03-22 17:44:59,018 - logger.py - ERROR 登录失败
Traceback (most recent call last):
  File "D:\py_workspace\dayan\case\test_日志登录测试.py", line 19, in test_login
    self.assertEqual(r.json()['message'],'请求成功142242')
  File "C:\Python34\lib\unittest\case.py", line 797, in assertEqual
    assertion_func(first, second, msg=msg)
  File "C:\Python34\lib\unittest\case.py", line 1170, in assertMultiLineEqual
    self.fail(self._formatMessage(msg, standardMsg))
  File "C:\Python34\lib\unittest\case.py", line 642, in fail
    raise self.failureException(msg)
AssertionError: '请求成功' != '请求成功142242'
- 请求成功
+ 请求成功142242

2019-03-22 17:44:59,023 - logger.py - INFO 获取验证码操作结果{'data': None, 'sysMark': None, 'code': '000000', 'message': '请求成功'}
2019-03-22 17:44:59,027 - logger.py - INFO 获取是否获取验证码成功:请求成功
2019-03-22 17:44:59,031 - logger.py - INFO 开始执行登录操作
2019-03-22 17:44:59,082 - logger.py - INFO 获取是否登录成功结果:请求成功
2019-03-22 17:44:59,086 - logger.py - INFO 获取登录成功之后的token:eyJ0eXAiOiJKV1QiLCJhbGciOiJIUzI1NiJ9.eyJ1aWQiOiIxMDk3Njg0MTI4Mjc2OTcxNTIyIiwiaXNzIjoiZGF5YW4iLCJuYW1lIjoi5p2o5YWI55SfIiwiZXhwIjoxNTUzNDIwNjk3LCJfIjoxNTUzMjQ3ODk3MjE0fQ.S5uYC9Moa4pYYMTd_oDD0FCAeT7Do5S6Gf5FtE9iJOQ
2019-03-22 17:46:11,940 - logger.py - INFO 开始登录前获取验证码操作,使用手机号18358331453
2019-03-22 17:46:12,025 - logger.py - ERROR 登录失败
Traceback (most recent call last):
  File "D:\py_workspace\dayan\case\test_日志登录测试.py", line 19, in test_login
    self.assertEqual(r.json()['message'],'请求成功142242')
  File "C:\Python34\lib\unittest\case.py", line 797, in assertEqual
    assertion_func(first, second, msg=msg)
  File "C:\Python34\lib\unittest\case.py", line 1170, in assertMultiLineEqual
    self.fail(self._formatMessage(msg, standardMsg))
  File "C:\Python34\lib\unittest\case.py", line 642, in fail
    raise self.failureException(msg)
AssertionError: '请求成功' != '请求成功142242'
- 请求成功
+ 请求成功142242

2019-03-22 17:46:12,030 - logger.py - INFO 获取验证码操作结果{'code': '000000', 'message': '请求成功', 'sysMark': None, 'data': None}
2019-03-22 17:46:12,034 - logger.py - INFO 获取是否获取验证码成功:请求成功
2019-03-22 17:46:12,037 - logger.py - INFO 开始执行登录操作
2019-03-22 17:46:12,094 - logger.py - INFO 获取是否登录成功结果:请求成功
2019-03-22 17:46:12,098 - logger.py - INFO 获取登录成功之后的token:eyJ0eXAiOiJKV1QiLCJhbGciOiJIUzI1NiJ9.eyJ1aWQiOiIxMDk3Njg0MTI4Mjc2OTcxNTIyIiwiaXNzIjoiZGF5YW4iLCJuYW1lIjoi5p2o5YWI55SfIiwiZXhwIjoxNTUzNDIwNzcwLCJfIjoxNTUzMjQ3OTcwMjE0fQ.KiIFdhQElmc8uvinM5g1UMpHVRUyJkphlaCyB9WEYDE
2019-03-22 17:53:46,343 - logger.py - INFO 开始登录前获取验证码操作,使用手机号18358331453
2019-03-22 17:53:46,420 - logger.py - INFO 获取验证码操作结果{'code': '000000', 'sysMark': None, 'message': '请求成功', 'data': None}
2019-03-22 17:53:46,425 - logger.py - INFO 获取是否获取验证码成功:请求成功
2019-03-22 17:53:46,429 - logger.py - INFO 开始执行登录操作
2019-03-22 17:53:46,505 - logger.py - INFO 获取是否登录成功结果:请求成功
2019-03-22 17:53:46,509 - logger.py - INFO 获取登录成功之后的token:eyJ0eXAiOiJKV1QiLCJhbGciOiJIUzI1NiJ9.eyJ1aWQiOiIxMDk3Njg0MTI4Mjc2OTcxNTIyIiwiaXNzIjoiZGF5YW4iLCJuYW1lIjoi5p2o5YWI55SfIiwiZXhwIjoxNTUzNDIxMjI0LCJfIjoxNTUzMjQ4NDI0NjI0fQ.g4B8BXenHWCH6LI_JoJZ1kYo5JtL6jSOsy2xpD7FNuo
